Workbook
Name list_mood: 'SETUP'!SETUP!$B$10:$B$14
Name list_energy: 'SETUP'!SETUP!$B$16:$B$20
Name list_stress: 'SETUP'!SETUP!$B$22:$B$26
Name list_yes_no: 'SETUP'!SETUP!$B$28:$B$29
Name list_task_status: 'SETUP'!SETUP!$B$31:$B$34
Name list_task_priority: 'SETUP'!SETUP!$B$36:$B$38
Name list_task_category: 'SETUP'!SETUP!$B$40:$B$44
Name list_goal_status: 'SETUP'!SETUP!$B$46:$B$48
Name list_goal_timeframe: 'SETUP'!SETUP!$B$50:$B$52
Name list_finance_type: 'SETUP'!SETUP!$B$54:$B$55
Name list_finance_category: 'SETUP'!SETUP!$B$57:$B$70
Name list_job_status: 'SETUP'!SETUP!$B$72:$B$79
Name list_health_symptom: 'SETUP'!SETUP!$B$81:$B$87
Name list_lh_test: 'SETUP'!SETUP!$B$89:$B$91
Name list_cycle_phase: 'SETUP'!SETUP!$B$93:$B$97

Sheet README
A1: EXCEL LIFE TRACKER
A2: Version 1.0 | Built: February 2026 | For: Michelle Humes
A5: WHAT IS THIS?
A6: This workbook helps you track all aspects of your life in one place:
A7: • Daily metrics (sleep, mood, energy, exercise)
A8: • Habits and streaks
A9: • Tasks and goals
A10: • Personal finances
A11: • Job search pipeline
A12: • Health and fertility tracking
A14: HOW TO USE
A15: 1. Start with the SETUP sheet | B15: Review and customize categories and lists
A16: 2. Visit the DASHBOARD daily | B16: Check your key metrics and trends
A17: 3. Add daily entries | B17: Use DAILY_LOG for daily metrics
A18: 4. Track habits | B18: Use HABIT_LOG to build consistency
A19: 5. Manage tasks | B19: Use TASKS for to-dos and GOALS for long-term targets
A20: 6. Log finances | B20: Use FINANCE to track income and expenses
A21: 7. Track job applications | B21: Use JOB_SEARCH for your career pipeline
A23: QUICK START TIPS
A24: ✓ All dropdown menus are configured in SETUP
A25: ✓ Tables auto-expand when you add new rows
A26: ✓ Dashboard updates automatically from your data
A27: ✓ Use consistent categories for better insights
A28: ✓ Sample data is included - feel free to delete it
A30: UPDATING CATEGORIES
A31: 1. Go to SETUP sheet
A32: 2. Find the list you want to edit
A33: 3. Add or modify values in the list columns
A34: 4. Named ranges will update automatically
A36: READING THE DASHBOARD
A37: • KPI Cards | B37: Show averages and totals for last 7 and 30 days
A38: • Trend Charts | B38: Display mood and sleep patterns over time
A39: • Spending Chart | B39: Shows expenses by category for current month
A40: • Job Pipeline | B40: Summary of application statuses
A42: NOTES
A43: • This workbook uses Excel 365 formulas
A44: • No macros or VBA required
A45: • Works on Windows and Mac
A46: • Keep backups of your data regularly

Sheet SETUP
A1: CONFIGURATION & LISTS
A3: Configuration
A4: Start Year | B4: 2026
A5: Start Date | B5: 46023
A6: Owner Name | B6: Michelle Humes
A8: Dropdown Lists
A9: List Name | B9: Values
A10: list_mood | B10: 1
B11: 2
B12: 3
B13: 4
B14: 5
A16: list_energy | B16: 1
B17: 2
B18: 3
B19: 4
B20: 5
A22: list_stress | B22: 1
B23: 2
B24: 3
B25: 4
B26: 5
A28: list_yes_no | B28: Yes
B29: No
A31: list_task_status | B31: Backlog
B32: Today
B33: In Progress
B34: Completed
A36: list_task_priority | B36: Low
B37: Medium
B38: High
A40: list_task_category | B40: Health
B41: Career
B42: Business
B43: Personal
B44: Relationships
A46: list_goal_status | B46: Active
B47: Paused
B48: Completed
A50: list_goal_timeframe | B50: Short
...

Sheet DASHBOARD
A1: LIFE TRACKER DASHBOARD
A2: Generated: 2026-02-03 06:33
A4: LAST 7 DAYS | E4: CHARTS & TRENDS
A5: Avg Sleep Hours | B5: =AVERAGEIFS(DAILY_LOG!$E:$E,DAILY_LOG!$A:$A,">="&TODAY()-6,DAILY_LOG!$A:$A,"<="&TODAY())
A6: Avg Mood | B6: =AVERAGEIFS(DAILY_LOG!$J:$J,DAILY_LOG!$A:$A,">="&TODAY()-6,DAILY_LOG!$A:$A,"<="&TODAY()) | E6: Note: Charts show visual trends for:
A7: Avg Energy | B7: =AVERAGEIFS(DAILY_LOG!$K:$K,DAILY_LOG!$A:$A,">="&TODAY()-6,DAILY_LOG!$A:$A,"<="&TODAY()) | E7: • Mood & Sleep patterns (last 30 days)
A8: Total Exercise (min) | B8: =SUMIFS(DAILY_LOG!$H:$H,DAILY_LOG!$A:$A,">="&TODAY()-6,DAILY_LOG!$A:$A,"<="&TODAY()) | E8: • Expense breakdown by category
E9: • Job pipeline funnel
A10: LAST 30 DAYS
A11: Avg Sleep Hours | B11: =AVERAGEIFS(DAILY_LOG!$E:$E,DAILY_LOG!$A:$A,">="&TODAY()-29,DAILY_LOG!$A:$A,"<="&TODAY()) | E11: Excel will auto-generate recommended
A12: Avg Mood | B12: =AVERAGEIFS(DAILY_LOG!$J:$J,DAILY_LOG!$A:$A,">="&TODAY()-29,DAILY_LOG!$A:$A,"<="&TODAY()) | E12: charts based on your data tables.
A13: Tasks Completed | B13: =COUNTIFS(TASKS!$D:$D,"Completed",TASKS!$F:$F,">="&TODAY()-29,TASKS!$F:$F,"<="&TODAY())
A14: Habit Completion % | B14: =IFERROR(COUNTIFS(HABIT_LOG!$E:$E,"Yes",HABIT_LOG!$A:$A,">="&TODAY()-29,HABIT_LOG!$A:$A,"<="&TODAY())/COUNTIFS(HABIT_LOG!$A:$A,">="&TODAY()-29,HABIT_LOG!$A:$A,"<="&TODAY()),0) | E14: To add charts:
E15: 1. Select data from any sheet
A16: CURRENT MONTH FINANCES | E16: 2. Insert > Recommended Charts
A17: Total Income | B17: =SUMIFS(FINANCE!$E:$E,FINANCE!$D:$D,"Income",FINANCE!$A:$A,">="&EOMONTH(TODAY(),-1)+1,FINANCE!$A:$A,"<="&EOMONTH(TODAY(),0)) | E17: 3. Copy chart to Dashboard
A18: Total Expenses | B18: =SUMIFS(FINANCE!$E:$E,FINANCE!$D:$D,"Expense",FINANCE!$A:$A,">="&EOMONTH(TODAY(),-1)+1,FINANCE!$A:$A,"<="&EOMONTH(TODAY(),0))
A19: Net Cash Flow | B19: =B17-B18
A21: JOB SEARCH PIPELINE
A22: Target | B22: =COUNTIF(JOB_SEARCH!$H:$H,"Target")
A23: Applied | B23: =COUNTIF(JOB_SEARCH!$H:$H,"Applied")
A24: Screening | B24: =COUNTIF(JOB_SEARCH!$H:$H,"Screening")
A25: Interview | B25: =COUNTIF(JOB_SEARCH!$H:$H,"Interview")
A26: Offer | B26: =COUNTIF(JOB_SEARCH!$H:$H,"Offer")

Sheet DAILY_LOG
A1: Date | B1: Day | C1: Week | D1: Month | E1: SleepHours | F1: SleepQuality | G1: Steps | H1: ExerciseMinutes | I1: WaterOz | J1: Mood | K1: Energy | L1: Stress | M1: Highlights | N1: Notes
A2: 46047.273 | B2: =TEXT(A2,"ddd") | C2: =WEEKNUM(A2) | D2: =TEXT(A2,"yyyy-mm") | E2: 8.2 | F2: 5 | G2: 7379 | H2: 30 | I2: 50 | J2: 5 | K2: 4 | L2: 3 | M2: Productive day | N2: Very energetic
A3: 46048.273 | B3: =TEXT(A3,"ddd") | C3: =WEEKNUM(A3) | D3: =TEXT(A3,"yyyy-mm") | E3: 8.4 | F3: 3 | G3: 9632 | H3: 57 | I3: 49 | J3: 3 | K3: 5 | L3: 3 | M3: Made progress on project | N3: Very energetic
A4: 46049.273 | B4: =TEXT(A4,"ddd") | C4: =WEEKNUM(A4) | D4: =TEXT(A4,"yyyy-mm") | E4: 6.7 | F4: 5 | G4: 8782 | H4: 30 | I4: 79 | J4: 5 | K4: 3 | L4: 1 | M4: Productive day | N4: Balanced day
A5: 46050.273 | B5: =TEXT(A5,"ddd") | C5: =WEEKNUM(A5) | D5: =TEXT(A5,"yyyy-mm") | E5: 8.5 | F5: 3 | G5: 6007 | H5: 15 | I5: 60 | J5: 5 | K5: 4 | L5: 1 | M5: Relaxing evening | N5: Need more sleep
A6: 46051.273 | B6: =TEXT(A6,"ddd") | C6: =WEEKNUM(A6) | D6: =TEXT(A6,"yyyy-mm") | E6: 6.4 | F6: 5 | G6: 11467 | H6: 41 | I6: 79 | J6: 5 | K6: 4 | L6: 2 | M6: Great workout! | N6: Need more sleep
A7: 46052.273 | B7: =TEXT(A7,"ddd") | C7: =WEEKNUM(A7) | D7: =TEXT(A7,"yyyy-mm") | E7: 8.5 | F7: 3 | G7: 9123 | H7: 2 | I7: 76 | J7: 5 | K7: 3 | L7: 2 | M7: Made progress on project | N7: Very energetic
A8: 46053.273 | B8: =TEXT(A8,"ddd") | C8: =WEEKNUM(A8) | D8: =TEXT(A8,"yyyy-mm") | E8: 7.9 | F8: 4 | G8: 11417 | H8: 1 | I8: 68 | J8: 3 | K8: 5 | L8: 3 | M8: Relaxing evening | N8: Felt good today
A9: 46054.273 | B9: =TEXT(A9,"ddd") | C9: =WEEKNUM(A9) | D9: =TEXT(A9,"yyyy-mm") | E9: 8.4 | F9: 4 | G9: 8814 | H9: 29 | I9: 78 | J9: 3 | K9: 5 | L9: 3 | M9: Coffee with friend | N9: A bit tired
A10: 46055.273 | B10: =TEXT(A10,"ddd") | C10: =WEEKNUM(A10) | D10: =TEXT(A10,"yyyy-mm") | E10: 7.5 | F10: 5 | G10: 7497 | H10: 19 | I10: 80 | J10: 4 | K10: 5 | L10: 1 | M10: Productive day | N10: Balanced day
A11: 46056.273 | B11: =TEXT(A11,"ddd") | C11: =WEEKNUM(A11) | D11: =TEXT(A11,"yyyy-mm") | E11: 6.2 | F11: 4 | G11: 11172 | H11: 18 | I11: 62 | J11: 5 | K11: 3 | L11: 1 | M11: Made progress on project | N11: Need more sleep

Sheet HABIT_LOG
A1: Date | B1: Habit | C1: Category | D1: Value | E1: Done | F1: Notes | H1: MONTHLY SUMMARY
A2: 46047.273 | B2: Morning Exercise | C2: Personal | D2: 27 | E2: No
A3: 46047.273 | B3: Read 30min | C3: Health | D3: 16 | E3: No | H3: Habit Completion Rate (Current Month)
A4: 46047.273 | B4: Walk 10k steps | C4: Personal | D4: 11 | E4: Yes | H4: Morning Exercise | I4: =IFERROR(COUNTIFS(tblHabits[Habit],"Morning Exercise",tblHabits[Done],"Yes",tblHabits[Date],">="&EOMONTH(TODAY(),-1)+1,tblHabits[Date],"<="&EOMONTH(TODAY(),0))/COUNTIFS(tblHabits[Habit],"Morning Exercise",tblHabits[Date],">="&EOMONTH(TODAY(),-1)+1,tblHabits[Date],"<="&EOMONTH(TODAY(),0)),0)
A5: 46047.273 | B5: Meditate | C5: Personal | D5: 14 | E5: Yes | H5: Read 30min | I5: =IFERROR(COUNTIFS(tblHabits[Habit],"Read 30min",tblHabits[Done],"Yes",tblHabits[Date],">="&EOMONTH(TODAY(),-1)+1,tblHabits[Date],"<="&EOMONTH(TODAY(),0))/COUNTIFS(tblHabits[Habit],"Read 30min",tblHabits[Date],">="&EOMONTH(TODAY(),-1)+1,tblHabits[Date],"<="&EOMONTH(TODAY(),0)),0)
A6: 46047.273 | B6: Track Finances | C6: Personal | D6: 9 | E6: No | H6: Meditate | I6: =IFERROR(COUNTIFS(tblHabits[Habit],"Meditate",tblHabits[Done],"Yes",tblHabits[Date],">="&EOMONTH(TODAY(),-1)+1,tblHabits[Date],"<="&EOMONTH(TODAY(),0))/COUNTIFS(tblHabits[Habit],"Meditate",tblHabits[Date],">="&EOMONTH(TODAY(),-1)+1,tblHabits[Date],"<="&EOMONTH(TODAY(),0)),0)
A7: 46048.273 | B7: Walk 10k steps | C7: Career | D7: 9 | E7: Yes
A8: 46048.273 | B8: Meditate | C8: Health | D8: 7 | E8: Yes
A9: 46048.273 | B9: Read 30min | C9: Personal | D9: 16 | E9: No
A10: 46048.273 | B10: Track Finances | C10: Personal | D10: 18 | E10: No
A11: 46049.273 | B11: Walk 10k steps | C11: Career | D11: 30 | E11: No
A12: 46049.273 | B12: Morning Exercise | C12: Health | D12: 28 | E12: No
A13: 46049.273 | B13: Track Finances | C13: Personal | D13: 2 | E13: Yes
A14: 46049.273 | B14: Read 30min | C14: Health | D14: 22 | E14: No
A15: 46049.273 | B15: Meditate | C15: Health | D15: 29 | E15: No
A16: 46050.273 | B16: Read 30min | C16: Health | D16: 9 | E16: No
A17: 46050.273 | B17: Track Finances | C17: Career | D17: 18 | E17: Yes
A18: 46050.273 | B18: Meditate | C18: Personal | D18: 14 | E18: No
... A43: 46056.273 | B43: Morning Exercise | C43: Health | D43: 21 | E43: No

Sheet TASKS
A1: Task | B1: Category | C1: Priority | D1: Status | E1: DueDate | F1: CompletedDate | G1: Notes | H1: IsOverdue
A2: Update resume | B2: Career | C2: High | D2: In Progress | E2: 46059.273 | G2: Focus on latest achievements | H2: =IF(AND(D2<>"Completed",E2<>"",E2<TODAY()),"Yes","No")
A3: Schedule dentist appointment | B3: Health | C3: Medium | D3: Today | E3: 46056.273 | H3: =IF(AND(D3<>"Completed",E3<>"",E3<TODAY()),"Yes","No")
A4: Review Q1 finances | B4: Personal | C4: High | D4: Backlog | E4: 46063.273 | G4: Check all accounts | H4: =IF(AND(D4<>"Completed",E4<>"",E4<TODAY()),"Yes","No")
A5: Plan Valentine's Day | B5: Relationships | C5: Medium | D5: Completed | E5: 46054.273 | F5: 46055.273 | G5: Reservations made | H5: =IF(AND(D5<>"Completed",E5<>"",E5<TODAY()),"Yes","No")
A6: Launch new product | B6: Business | C6: High | D6: In Progress | E6: 46070.273 | G6: Final testing phase | H6: =IF(AND(D6<>"Completed",E6<>"",E6<TODAY()),"Yes","No")
A7: Read "Atomic Habits" | B7: Personal | C7: Low | D7: Backlog | E7: 46086.273 | G7: 50% complete | H7: =IF(AND(D7<>"Completed",E7<>"",E7<TODAY()),"Yes","No")
A8: Update LinkedIn profile | B8: Career | C8: Medium | D8: Today | E8: 46056.273 | H8: =IF(AND(D8<>"Completed",E8<>"",E8<TODAY()),"Yes","No")
A9: Meal prep for week | B9: Health | C9: Medium | D9: Completed | E9: 46055.273 | F9: 46055.273 | H9: =IF(AND(D9<>"Completed",E9<>"",E9<TODAY()),"Yes","No")

Sheet GOALS
A1: Goal | B1: Category | C1: Timeframe | D1: Status | E1: StartDate | F1: TargetDate | G1: TargetValue | H1: CurrentValue | I1: ProgressPct | J1: Notes
A2: Land new job with $120k+ salary | B2: Career | C2: Medium | D2: Active | E2: 46023 | F2: 46203 | G2: 1 | H2: 0.3 | I2: =IF(G2="","",MIN(1,H2/G2)) | J2: Applied to 15 companies so far
A3: Save $10,000 emergency fund | B3: Personal | C3: Short | D3: Active | E3: 46023 | F3: 46387 | G3: 10000 | H3: 4500 | I3: =IF(G3="","",MIN(1,H3/G3)) | J3: On track
A4: Launch 3 new Etsy products | B4: Business | C4: Short | D4: Active | E4: 46037 | F4: 46112 | G4: 3 | H4: 1 | I4: =IF(G4="","",MIN(1,H4/G4)) | J4: 1st product launched
A5: Read 24 books this year | B5: Personal | C5: Long | D5: Active | E5: 46023 | F5: 46387 | G5: 24 | H5: 3 | I5: =IF(G5="","",MIN(1,H5/G5)) | J5: 2 books per month goal
A6: Get pregnant | B6: Health | C6: Medium | D6: Active | E6: 45962 | F6: 46265 | G6: 1 | H6: 0.5 | I6: =IF(G6="","",MIN(1,H6/G6)) | J6: Tracking cycles actively
A7: Build professional network | B7: Career | C7: Long | D7: Active | E7: 46023 | F7: 46387 | G7: 50 | H7: 12 | I7: =IF(G7="","",MIN(1,H7/G7)) | J7: Attending monthly meetups

Sheet FINANCE
A1: Date | B1: Description | C1: Category | D1: Type | E1: Amount | F1: Account | G1: Owner | H1: Notes | J1: MONTHLY SUMMARY
A2: 46055.273 | B2: Salary - Main Job | C2: Income | D2: Income | E2: 4500 | F2: Chase Checking | G2: Michelle | H2: Bi-weekly payroll
A3: 46069.273 | B3: Salary - Main Job | C3: Income | D3: Income | E3: 4500 | F3: Chase Checking | G3: Michelle | H3: Bi-weekly payroll | J3: Current Month
A4: 46064.273 | B4: Etsy Sales | C4: Business | D4: Income | E4: 450 | F4: Business Account | G4: Michelle | H4: Wedding planners sold | J4: Total Income | K4: =SUMIFS(tblFinance[Amount],tblFinance[Type],"Income",tblFinance[Date],">="&EOMONTH(TODAY(),-1)+1,tblFinance[Date],"<="&EOMONTH(TODAY(),0))
A5: 46055.273 | B5: Rent Payment | C5: Housing | D5: Expense | E5: 1800 | F5: Chase Checking | G5: Michelle | H5: Monthly rent | J5: Total Expenses | K5: =SUMIFS(tblFinance[Amount],tblFinance[Type],"Expense",tblFinance[Date],">="&EOMONTH(TODAY(),-1)+1,tblFinance[Date],"<="&EOMONTH(TODAY(),0))
A6: 46057.273 | B6: Electric Bill | C6: Utilities | D6: Expense | E6: 120 | F6: Chase Checking | G6: Michelle | H6: January usage | J6: Net Cash Flow | K6: =K4-K5
A7: 46059.273 | B7: Trader Joes | C7: Groceries | D7: Expense | E7: 85 | F7: Chase Credit | G7: Michelle | H7: Weekly shopping
A8: 46061.273 | B8: Target | C8: Shopping | D8: Expense | E8: 45 | F8: Chase Credit | G8: Michelle | H8: Household items
A9: 46062.273 | B9: Starbucks | C9: Dining | D9: Expense | E9: 12 | F9: Chase Credit | G9: Michelle | H9: Coffee meeting
A10: 46064.273 | B10: LA Fitness | C10: Fitness | D10: Expense | E10: 50 | F10: Chase Checking | G10: Michelle | H10: Monthly membership
A11: 46066.273 | B11: Whole Foods | C11: Groceries | D11: Expense | E11: 95 | F11: Chase Credit | G11: Michelle | H11: Weekly shopping
A12: 46068.273 | B12: Netflix | C12: Subscriptions | D12: Expense | E12: 15.99 | F12: Chase Credit | G12: Michelle | H12: Monthly subscription
A13: 46070.273 | B13: Gas Station | C13: Transportation | D13: Expense | E13: 45 | F13: Chase Credit | G13: Michelle | H13: Fill up
A14: 46072.273 | B14: Amazon | C14: Shopping | D14: Expense | E14: 67 | F14: Chase Credit | G14: Michelle | H14: Office supplies

Sheet JOB_SEARCH
A1: Company | B1: Role | C1: Level | D1: SalaryMin | E1: SalaryMax | F1: Location | G1: Remote | H1: Status | I1: AppliedDate | J1: LastContact | K1: NextAction | L1: NextActionDate | M1: Notes | O1: PIPELINE SUMMARY
A2: Google | B2: Product Manager | C2: Senior | D2: 140000 | E2: 180000 | F2: Mountain View, CA | G2: Yes | H2: Interview | I2: 46032 | J2: 46050 | K2: Prepare for final round | L2: 46058 | M2: Very interested - great culture fit
A3: Microsoft | B3: Program Manager | C3: Mid-level | D3: 120000 | E3: 150000 | F3: Seattle, WA | G3: Yes | H3: Applied | I3: 46037 | J3: 46037 | K3: Follow up if no response | L3: 46054 | M3: Strong technical team | O3: Status Counts
A4: Amazon | B4: Technical Program Manager | C4: Senior | D4: 135000 | E4: 165000 | F4: Austin, TX | G4: No | H4: Screening | I4: 46027 | J4: 46042 | K4: Phone screen scheduled | L4: 46056 | M4: Fast-paced environment | O4: Target | P4: =COUNTIF(tblJobs[Status],"Target")
A5: Apple | B5: Product Manager | C5: Senior | D5: 145000 | E5: 185000 | F5: Cupertino, CA | G5: No | H5: Target | K5: Submit application | L5: 46060 | M5: Dream company | O5: Applied | P5: =COUNTIF(tblJobs[Status],"Applied")
A6: Salesforce | B6: Senior Product Manager | C6: Senior | D6: 130000 | E6: 160000 | F6: San Francisco, CA | G6: Yes | H6: Rejected | I6: 46025 | J6: 46047 | M6: Not a good fit per recruiter | O6: Screening | P6: =COUNTIF(tblJobs[Status],"Screening")
A7: Meta | B7: Product Manager | C7: Senior | D7: 150000 | E7: 190000 | F7: Menlo Park, CA | G7: Yes | H7: Interview | I7: 46034 | J7: 46052 | K7: Technical interview prep | L7: 46061 | M7: Exciting product area | O7: Interview | P7: =COUNTIF(tblJobs[Status],"Interview")
A8: Stripe | B8: Product Manager | C8: Mid-level | D8: 125000 | E8: 155000 | F8: Remote | G8: Yes | H8: Applied | I8: 46042 | J8: 46042 | K8: Wait for response | L8: 46063 | M8: Fintech experience relevant | O8: Offer | P8: =COUNTIF(tblJobs[Status],"Offer")
O10: Avg Salary Range
O11: Min | P11: =AVERAGE(tblJobs[SalaryMin])
O12: Max | P12: =AVERAGE(tblJobs[SalaryMax])

Sheet HEALTH_FERTILITY
A1: Date | B1: CycleDay | C1: DPO | D1: Phase | E1: Temperature | F1: LHTest | G1: Symptoms | H1: Mood | I1: Energy | J1: SexualActivity | K1: Notes
A2: 46036.273 | B2: 5 | D2: Follicular | E2: 97.3 | F2: Not Taken | G2: Bloating | H2: 4 | I2: 3 | J2: No
A3: 46037.273 | B3: 6 | D3: Follicular | E3: 97.2 | F3: Not Taken | G3: Tenderness | H3: 4 | I3: 4 | J3: No
A4: 46038.273 | B4: 7 | D4: Follicular | E4: 98 | F4: Not Taken | H4: 4 | I4: 3 | J4: No
A5: 46039.273 | B5: 8 | D5: Follicular | E5: 97.6 | F5: Not Taken | G5: Tenderness | H5: 5 | I5: 4 | J5: Yes
A6: 46040.273 | B6: 9 | D6: Follicular | E6: 97.9 | F6: Not Taken | H6: 3 | I6: 4 | J6: No
A7: 46041.273 | B7: 10 | D7: Fertile | E7: 98.5 | F7: Not Taken | G7: Cramps | H7: 4 | I7: 4 | J7: No
A8: 46042.273 | B8: 11 | D8: Fertile | E8: 97.5 | F8: Negative | G8: Bloating | H8: 3 | I8: 5 | J8: No
A9: 46043.273 | B9: 12 | D9: Fertile | E9: 97.9 | F9: Negative | G9: Cramps | H9: 3 | I9: 5 | J9: Yes
A10: 46044.273 | B10: 13 | D10: Ovulation | E10: 97.4 | F10: Positive | G10: Cramps | H10: 5 | I10: 5 | J10: Yes
A11: 46045.273 | B11: 14 | D11: Ovulation | E11: 97.5 | F11: Positive | G11: Tenderness | H11: 5 | I11: 3 | J11: No
A12: 46046.273 | B12: 15 | C12: 1 | D12: Luteal | E12: 98.5 | F12: Negative | G12: Bloating | H12: 3 | I12: 5 | J12: No
A13: 46047.273 | B13: 16 | C13: 2 | D13: Luteal | E13: 98 | F13: Negative | G13: Cramps | H13: 4 | I13: 5 | J13: No
A14: 46048.273 | B14: 17 | C14: 3 | D14: Luteal | E14: 97.9 | F14: Negative | G14: Fatigue | H14: 5 | I14: 4 | J14: Yes
A15: 46049.273 | B15: 18 | C15: 4 | D15: Luteal | E15: 97.4 | F15: Negative | G15: Tenderness | H15: 3 | I15: 3 | J15: Yes
A16: 46050.273 | B16: 19 | C16: 5 | D16: Luteal | E16: 97.3 | F16: Negative | H16: 5 | I16: 5 | J16: No
A17: 46051.273 | B17: 20 | C17: 6 | D17: Luteal | E17: 98.3 | F17: Negative | G17: Tenderness | H17: 4 | I17: 4 | J17: No
A18: 46052.273 | B18: 21 | C18: 7 | D18: Luteal | E18: 97.6 | F18: Negative | H18: 3 | I18: 3 | J18: No
A19: 46053.273 | B19: 22 | C19: 8 | D19: Luteal | E19: 97.5 | F19: Negative | G19: Fatigue | H19: 3 | I19: 3 | J19: Yes
A20: 46054.273 | B20: 23 | C20: 9 | D20: Luteal | E20: 98.3 | F20: Negative | G20: Cramps | H20: 5 | I20: 3 | J20: Yes
A21: 46055.273 | B21: 24 | C21: 10 | D21: Luteal | E21: 97.3 | F21: Negative | G21: Fatigue | H21: 3 | I21: 4 | J21: No
