Workbook

Sheet Chore Chart
A1: KIDS CHORE CHART SYSTEM
A4: CHILD'S NAME: | F4: WEEK OF: | J4: POINTS GOAL:
J5: 35
A7: DAILY CHORES
A8: # | B8: CHORE | C8: MON | D8: TUE | E8: WED | F8: THU | G8: FRI | H8: SAT | I8: SUN | J8: DONE | K8: POINTS
A9: 1 | B9: Make Bed | J9: =COUNTIF(C9:I9,"✓") | K9: =J9
A10: 2 | B10: Brush Teeth (AM) | J10: =COUNTIF(C10:I10,"✓") | K10: =J10
A11: 3 | B11: Brush Teeth (PM) | J11: =COUNTIF(C11:I11,"✓") | K11: =J11
A12: 4 | B12: Pick Up Toys | J12: =COUNTIF(C12:I12,"✓") | K12: =J12
A13: 5 | B13: Set the Table | J13: =COUNTIF(C13:I13,"✓") | K13: =J13
A14: 6 | B14: Clear Dishes | J14: =COUNTIF(C14:I14,"✓") | K14: =J14
A15: 7 | B15: Put Clothes Away | J15: =COUNTIF(C15:I15,"✓") | K15: =J15
A16: 8 | B16: Pack School Bag | J16: =COUNTIF(C16:I16,"✓") | K16: =J16
A17: 9 | B17: Feed Pet | J17: =COUNTIF(C17:I17,"✓") | K17: =J17
A18: 10 | B18: Tidy Bedroom | J18: =COUNTIF(C18:I18,"✓") | K18: =J18
A20: WEEKLY CHORES
A21: # | B21: CHORE | C21: MON | D21: TUE | E21: WED | F21: THU | G21: FRI | H21: SAT | I21: SUN | J21: DONE | K21: POINTS
A22: 1 | B22: Clean Room Thoroughly | J22: =COUNTIF(C22:I22,"✓") | K22: =J22*2
A23: 2 | B23: Take Out Trash | J23: =COUNTIF(C23:I23,"✓") | K23: =J23*2
A24: 3 | B24: Help with Laundry | J24: =COUNTIF(C24:I24,"✓") | K24: =J24*2
A25: 4 | B25: Vacuum / Sweep | J25: =COUNTIF(C25:I25,"✓") | K25: =J25*2
A26: 5 | B26: Organize Bookshelf | J26: =COUNTIF(C26:I26,"✓") | K26: =J26*2
A28: WEEKLY SUMMARY
A29: Total Completed: | D29: =SUM(J9:J18,J22:J26) | F29: Total Points: | I29: =SUM(K9:K18,K22:K26)
A30: Progress: | D30: =IF(J5=0,0,SUM(K9:K18,K22:K26)/J5) | F30: Reward Status: | I30: =IF(SUM(K9:K18,K22:K26)>=J5,"REWARD EARNED!","Keep Going!")
A32: Progress Bar: | D32: =IF(J5=0,0,SUM(K9:K18,K22:K26)/J5) | E32: =IF(J5=0,0,SUM(K9:K18,K22:K26)/J5) | F32: =IF(J5=0,0,SUM(K9:K18,K22:K26)/J5) | G32: =IF(J5=0,0,SUM(K9:K18,K22:K26)/J5) | H32: =IF(J5=0,0,SUM(K9:K18,K22:K26)/J5) | I32: =IF(J5=0,0,SUM(K9:K18,K22:K26)/J5) | J32: =IF(J5=0,0,SUM(K9:K18,K22:K26)/J5) | K32: =IF(J5=0,0,SUM(K9:K18,K22:K26)/J5)
A34: NOTES & REWARD DESCRIPTION

Sheet Weekly Summary
A1: WEEKLY PROGRESS SUMMARY
A4: DAY-BY-DAY COMPLETION RATE
B5: DAY | C5: DAILY DONE | D5: DAILY TOTAL | E5: WEEKLY DONE | F5: WEEKLY TOTAL | G5: ALL DONE | H5: ALL TOTAL | I5: % COMPLETE | J5: STATUS
A6: 1 | B6: Monday | C6: =COUNTIF('Chore Chart'!C9:C18,"✓") | D6: 10 | E6: =COUNTIF('Chore Chart'!C22:C26,"✓") | F6: 5 | G6: =C6+E6 | H6: =D6+F6 | I6: =IF(H6=0,0,G6/H6) | J6: =IF(I6>=0.8,"Great!",IF(I6>=0.5,"Good","Needs Work"))
A7: 2 | B7: Tuesday | C7: =COUNTIF('Chore Chart'!D9:D18,"✓") | D7: 10 | E7: =COUNTIF('Chore Chart'!D22:D26,"✓") | F7: 5 | G7: =C7+E7 | H7: =D7+F7 | I7: =IF(H7=0,0,G7/H7) | J7: =IF(I7>=0.8,"Great!",IF(I7>=0.5,"Good","Needs Work"))
A8: 3 | B8: Wednesday | C8: =COUNTIF('Chore Chart'!E9:E18,"✓") | D8: 10 | E8: =COUNTIF('Chore Chart'!E22:E26,"✓") | F8: 5 | G8: =C8+E8 | H8: =D8+F8 | I8: =IF(H8=0,0,G8/H8) | J8: =IF(I8>=0.8,"Great!",IF(I8>=0.5,"Good","Needs Work"))
A9: 4 | B9: Thursday | C9: =COUNTIF('Chore Chart'!F9:F18,"✓") | D9: 10 | E9: =COUNTIF('Chore Chart'!F22:F26,"✓") | F9: 5 | G9: =C9+E9 | H9: =D9+F9 | I9: =IF(H9=0,0,G9/H9) | J9: =IF(I9>=0.8,"Great!",IF(I9>=0.5,"Good","Needs Work"))
A10: 5 | B10: Friday | C10: =COUNTIF('Chore Chart'!G9:G18,"✓") | D10: 10 | E10: =COUNTIF('Chore Chart'!G22:G26,"✓") | F10: 5 | G10: =C10+E10 | H10: =D10+F10 | I10: =IF(H10=0,0,G10/H10) | J10: =IF(I10>=0.8,"Great!",IF(I10>=0.5,"Good","Needs Work"))
A11: 6 | B11: Saturday | C11: =COUNTIF('Chore Chart'!H9:H18,"✓") | D11: 10 | E11: =COUNTIF('Chore Chart'!H22:H26,"✓") | F11: 5 | G11: =C11+E11 | H11: =D11+F11 | I11: =IF(H11=0,0,G11/H11) | J11: =IF(I11>=0.8,"Great!",IF(I11>=0.5,"Good","Needs Work"))
A12: 7 | B12: Sunday | C12: =COUNTIF('Chore Chart'!I9:I18,"✓") | D12: 10 | E12: =COUNTIF('Chore Chart'!I22:I26,"✓") | F12: 5 | G12: =C12+E12 | H12: =D12+F12 | I12: =IF(H12=0,0,G12/H12) | J12: =IF(I12>=0.8,"Great!",IF(I12>=0.5,"Good","Needs Work"))
A14: OVERALL WEEKLY STATS
A15: Total Check-Marks | F15: =SUM(G6:G12)
A16: Total Possible | F16: =SUM(H6:H12)
A17: Weekly Completion Rate | F17: =IF(SUM(H6:H12)=0,0,SUM(G6:G12)/SUM(H6:H12))
A18: Total Points Earned | F18: ='Chore Chart'!I29
A19: Points Goal | F19: ='Chore Chart'!J5
A20: Reward Progress | F20: =IF('Chore Chart'!J5=0,0,'Chore Chart'!I29/'Chore Chart'!J5)

Sheet Reward Tracker
A1: REWARD TRACKER
A4: THIS WEEK'S REWARD STATUS
A5: Points Earned This Week: | D5: ='Chore Chart'!I29 | F5: of | G5: ='Chore Chart'!J5
A6: Progress Toward Reward: | D6: =IF('Chore Chart'!J5=0,0,'Chore Chart'!I29/'Chore Chart'!J5) | F6: =IF('Chore Chart'!I29>='Chore Chart'!J5,"REWARD EARNED!","Keep Working!")
A7: Progress Bar: | D7: =IF('Chore Chart'!J5=0,0,'Chore Chart'!I29/'Chore Chart'!J5) | E7: =IF('Chore Chart'!J5=0,0,'Chore Chart'!I29/'Chore Chart'!J5) | F7: =IF('Chore Chart'!J5=0,0,'Chore Chart'!I29/'Chore Chart'!J5) | G7: =IF('Chore Chart'!J5=0,0,'Chore Chart'!I29/'Chore Chart'!J5) | H7: =IF('Chore Chart'!J5=0,0,'Chore Chart'!I29/'Chore Chart'!J5)
A9: REWARD BANK — MULTI-WEEK TRACKER
A10: # | B10: WEEK | C10: POINTS EARNED | D10: POINTS GOAL | E10: % ACHIEVED | F10: REWARD EARNED? | G10: REWARD GIVEN | H10: NOTES
A11: 1 | B11: Week 1 | E11: =IF(D11="","",(IF(D11=0,0,C11/D11))) | F11: =IF(D11="","",IF(C11>=D11,"YES","NO"))
A12: 2 | B12: Week 2 | E12: =IF(D12="","",(IF(D12=0,0,C12/D12))) | F12: =IF(D12="","",IF(C12>=D12,"YES","NO"))
A13: 3 | B13: Week 3 | E13: =IF(D13="","",(IF(D13=0,0,C13/D13))) | F13: =IF(D13="","",IF(C13>=D13,"YES","NO"))
A14: 4 | B14: Week 4 | E14: =IF(D14="","",(IF(D14=0,0,C14/D14))) | F14: =IF(D14="","",IF(C14>=D14,"YES","NO"))
A15: 5 | B15: Week 5 | E15: =IF(D15="","",(IF(D15=0,0,C15/D15))) | F15: =IF(D15="","",IF(C15>=D15,"YES","NO"))
A16: 6 | B16: Week 6 | E16: =IF(D16="","",(IF(D16=0,0,C16/D16))) | F16: =IF(D16="","",IF(C16>=D16,"YES","NO"))
A17: 7 | B17: Week 7 | E17: =IF(D17="","",(IF(D17=0,0,C17/D17))) | F17: =IF(D17="","",IF(C17>=D17,"YES","NO"))
A18: 8 | B18: Week 8 | E18: =IF(D18="","",(IF(D18=0,0,C18/D18))) | F18: =IF(D18="","",IF(C18>=D18,"YES","NO"))
A20: CUMULATIVE STATS
A21: Total Points Earned (All Weeks) | F21: =SUM(C11:C18)
A22: Total Rewards Earned | F22: =COUNTIF(F11:F18,"YES")
A23: Average Weekly Completion | F23: =IF(COUNTA(E11:E18)=0,0,AVERAGE(E11:E18))

Sheet Instructions
A1: HOW TO USE YOUR CHORE CHART SYSTEM
A4: GETTING STARTED
B5: Enter your child's name in the 'Child's Name' field on the Chore Chart tab.
B6: Enter the current week's start date in the 'Week Of' field.
B7: Set a Points Goal — this is the number of points needed to earn a reward.
B8: Customize chore names by clicking on any chore in the yellow-tinted cells.
A10: TRACKING DAILY CHORES
B11: Each day, mark completed chores with a ✓ (checkmark) in the day's column.
B12: Use the dropdown or type ✓ directly into the cell.
B13: Daily chores earn 1 point per completion.
B14: The 'DONE' column auto-counts how many days each chore was completed.
A16: TRACKING WEEKLY CHORES
B17: Weekly chores are bigger tasks done once or a few times per week.
B18: Mark them the same way — with a ✓ on the day completed.
B19: Weekly chores earn 2 points per completion (double daily chores).
A21: UNDERSTANDING THE SUMMARY
B22: Total Completed: Total number of individual chore check-marks.
B23: Total Points: Sum of all points (daily = 1pt, weekly = 2pt each).
B24: Progress: Shows percentage toward your points goal.
B25: Reward Status: Automatically shows 'REWARD EARNED!' when goal is met.
B26: Progress Bar: Visual representation of progress toward the reward.
A28: USING THE WEEKLY SUMMARY TAB
B29: This tab auto-calculates daily completion rates for each day of the week.
B30: See which days your child is most/least consistent.
B31: A bar chart shows at-a-glance daily performance.
B32: Overall stats track total completion rate and reward progress.
A34: USING THE REWARD TRACKER TAB
B35: The top section links to this week's Chore Chart data automatically.
B36: The Reward Bank below lets you log results from multiple weeks.
B37: Enter each week's points earned and goal to track long-term progress.
B38: Cumulative stats show total rewards earned and average completion.
A40: TIPS FOR SUCCESS
B41: Set realistic goals — start with a lower point threshold and increase.
B42: Let your child choose their reward to increase motivation.
B43: Review the chart together each evening as a routine.
B44: Celebrate progress, not just perfection — the progress bar helps!
B45: Print the Chore Chart tab for fridge display if desired.
A47: EDITABLE VS LOCKED CELLS
B48: Yellow-tinted cells = Editable (chore names, check marks, notes, names).
B49: White/colored cells with formulas = Auto-calculated (do not edit).
...
